Workbook

Sheet SLA_Targets
A1: Priority | B1: First_Response_Target_Hours | C1: Resolution_Target_Hours
A2: Critical | B2: 0.5 | C2: 4
A3: High | B3: 1 | C3: 8
A4: Medium | B4: 4 | C4: 24
A5: Low | B5: 8 | C5: 48

Sheet Agent_Master
A1: Agent_ID | B1: Agent_Name | C1: Support_Team | D1: Experience_Years | E1: Location
A2: A001 | B2: Riya Shah | C2: Workplace Support | D2: 4.2 | E2: Mumbai
A3: A002 | B3: Kabir Mehta | C3: Workplace Support | D3: 2.1 | E3: Pune
A4: A003 | B4: Aman Verma | C4: Identity & Access | D4: 5.6 | E4: Bengaluru
A5: A004 | B5: Neha Iyer | C5: Identity & Access | D5: 3.4 | E5: Bengaluru
A6: A005 | B6: Sana Khan | C6: Business Apps | D6: 6.3 | E6: Mumbai
A7: A006 | B7: Arjun Rao | C7: Business Apps | D7: 1.8 | E7: Hyderabad
A8: A007 | B8: Meera Nair | C8: Network & Infra | D8: 7.1 | E8: Pune
A9: A008 | B9: Dev Malhotra | C9: Network & Infra | D9: 3 | E9: Delhi
A10: A009 | B10: Ishita Bose | C10: Workplace Support | D10: 1.2 | E10: Kolkata
A11: A010 | B11: Rohan Sen | C11: Business Apps | D11: 4.8 | E11: Kolkata
A12: A011 | B12: Tanya Joshi | C12: Identity & Access | D12: 2.7 | E12: Delhi
A13: A012 | B13: Vikram Pillai | C13: Network & Infra | D13: 5.1 | E13: Hyderabad
A16: Row Labels | B16: Sum of Experience_Years
A17: Business Apps | B17: 12.9
A18: Arjun Rao | B18: 1.8
A19: Rohan Sen | B19: 4.8
A20: Sana Khan | B20: 6.3
A21: Identity & Access | B21: 11.7
A22: Aman Verma | B22: 5.6
A23: Neha Iyer | B23: 3.4
A24: Tanya Joshi | B24: 2.7
A25: Network & Infra | B25: 15.2
A26: Dev Malhotra | B26: 3
A27: Meera Nair | B27: 7.1
A28: Vikram Pillai | B28: 5.1
... A33: Grand Total | B33: 47.3

Sheet Raw_Data
A1: Ticket_ID | B1: Created_At | C1: First_Response_At | D1: Resolved_At | E1: Status | F1: Priority | G1: Issue_Category | H1: Department | I1: Channel | J1: Agent_ID | K1: Reopened | L1: CSAT_Score | M1: Agent_name | N1: Support_team | O1: Agent_exp | P1: Agent_location
A2: TKT-0001 | B2: 46175.416 | C2: 46175.666 | E2: In Progress | F2: Medium | G2: Password / Access | H2: Marketing | I2: Phone | J2: A003 | K2: No | M2: Aman Verma | N2: Identity & Access | O2: 5.6 | P2: Bengaluru
A3: TKT-0002 | B3: 46135.922 | C3: 46135.938 | D3: 46136.028 | E3: Resolved | F3: Critical | G3: ERP / Finance App | H3: Product | I3: Portal | J3: A005 | K3: No | L3: 4 | M3: Sana Khan | N3: Business Apps | O3: 6.3 | P3: Mumbai
A4: TKT-0003 | B4: 46146.728 | C4: 46146.814 | D4: 46148.227 | E4: Closed | F4: Medium | G4: CRM / Sales App | H4: Engineering | I4: Portal | J4: A010 | K4: No | L4: 4 | M4: Rohan Sen | N4: Business Apps | O4: 4.8 | P4: Kolkata
A5: TKT-0004 | B5: 46188.391 | C5: 46188.408 | D5: 46188.517 | E5: Resolved | F5: Critical | G5: Laptop / Hardware | H5: Human Resources | I5: Portal | J5: A001 | K5: No | L5: 4 | M5: Riya Shah | N5: Workplace Support | O5: 4.2 | P5: Mumbai
A6: TKT-0005 | B6: 46184.125 | C6: 46184.248 | D6: 46186.192 | E6: Closed | F6: Medium | G6: Laptop / Hardware | H6: Marketing | I6: Portal | J6: A002 | K6: No | L6: 3 | M6: Kabir Mehta | N6: Workplace Support | O6: 2.1 | P6: Pune
A7: TKT-0006 | B7: 46199.228 | C7: 46199.276 | D7: 46199.51 | E7: Resolved | F7: High | G7: Server / Connectivity | H7: Sales | I7: Phone | J7: A008 | K7: Yes | L7: 2 | M7: Dev Malhotra | N7: Network & Infra | O7: 3 | P7: Delhi
A8: TKT-0007 | B8: 46196.938 | C8: 46196.982 | D8: 46197.225 | E8: Closed | F8: High | G8: Password / Access | H8: Product | I8: Portal | J8: A011 | K8: No | L8: 4 | M8: Tanya Joshi | N8: Identity & Access | O8: 2.7 | P8: Delhi
A9: TKT-0008 | B9: 46124.164 | C9: 46124.179 | D9: 46124.693 | E9: Closed | F9: High | G9: Laptop / Hardware | H9: Operations | I9: Email | J9: A001 | K9: No | L9: 5 | M9: Riya Shah | N9: Workplace Support | O9: 4.2 | P9: Mumbai
A10: TKT-0009 | B10: 46202.51 | C10: 46202.522 | D10: 46202.589 | E10: Resolved | F10: Critical | G10: Password / Access | H10: Human Resources | I10: Phone | J10: A003 | K10: No | L10: 4 | M10: Aman Verma | N10: Identity & Access | O10: 5.6 | P10: Bengaluru
A11: TKT-0010 | B11: 46159.479 | C11: 46159.508 | D11: 46159.69 | E11: Closed | F11: Critical | G11: Server / Connectivity | H11: Product | I11: Chat | J11: A012 | K11: No | L11: 3 | M11: Vikram Pillai | N11: Network & Infra | O11: 5.1 | P11: Hyderabad
A12: TKT-0011 | B12: 46119.55 | C12: 46119.653 | D12: 46119.88 | E12: Closed | F12: Medium | G12: Email / Collaboration | H12: Marketing | I12: Portal | J12: A001 | K12: No | L12: 5 | M12: Riya Shah | N12: Workplace Support | O12: 4.2 | P12: Mumbai
A13: TKT-0012 | B13: 46199.004 | C13: 46199.18 | E13: In Progress | F13: Medium | G13: CRM / Sales App | H13: Product | I13: Portal | J13: A006 | K13: No | M13: Arjun Rao | N13: Business Apps | O13: 1.8 | P13: Hyderabad
A14: TKT-0013 | B14: 46119.218 | C14: 46119.302 | D14: 46119.644 | E14: Closed | F14: Medium | G14: Email / Collaboration | H14: Marketing | I14: Portal | J14: A001 | K14: No | L14: 4 | M14: Riya Shah | N14: Workplace Support | O14: 4.2 | P14: Mumbai
A15: TKT-0014 | B15: 46165.819 | C15: 46165.929 | D15: 46166.299 | E15: Closed | F15: Low | G15: Printer / Peripheral | H15: Sales | I15: Email | J15: A001 | K15: No | L15: 5 | M15: Riya Shah | N15: Workplace Support | O15: 4.2 | P15: Mumbai
A16: TKT-0015 | B16: 46157.51 | C16: 46157.69 | D16: 46158.271 | E16: Resolved | F16: Medium | G16: Laptop / Hardware | H16: Engineering | I16: Portal | J16: A009 | K16: No | L16: 4 | M16: Ishita Bose | N16: Workplace Support | O16: 1.2 | P16: Kolkata
A17: TKT-0016 | B17: 46195.99 | C17: 46196.255 | D17: 46197.355 | E17: Closed | F17: Medium | G17: Laptop / Hardware | H17: Marketing | I17: Portal | J17: A009 | K17: No | L17: 4 | M17: Ishita Bose | N17: Workplace Support | O17: 1.2 | P17: Kolkata
A18: TKT-0017 | B18: 46138.651 | C18: 46138.801 | D18: 46139.452 | E18: Closed | F18: Medium | G18: Laptop / Hardware | H18: Operations | I18: Portal | J18: A001 | K18: No | L18: 4 | M18: Riya Shah | N18: Workplace Support | O18: 4.2 | P18: Mumbai
A19: TKT-0018 | B19: 46137.051 | C19: 46137.113 | D19: 46137.381 | E19: Closed | F19: High | G19: Email / Collaboration | H19: Operations | I19: Email | J19: A009 | K19: No | L19: 4 | M19: Ishita Bose | N19: Workplace Support | O19: 1.2 | P19: Kolkata
A20: TKT-0019 | B20: 46180.083 | C20: 46180.121 | D20: 46180.475 | E20: Closed | F20: High | G20: CRM / Sales App | H20: Operations | I20: Portal | J20: A006 | K20: No | L20: 4 | M20: Arjun Rao | N20: Business Apps | O20: 1.8 | P20: Hyderabad
A21: TKT-0020 | B21: 46199.074 | C21: 46199.084 | D21: 46199.144 | E21: Closed | F21: Critical | G21: VPN / Network | H21: Legal | I21: Email | J21: A007 | K21: No | L21: 5 | M21: Meera Nair | N21: Network & Infra | O21: 7.1 | P21: Pune
A22: TKT-0021 | B22: 46198.26 | C22: 46198.387 | D22: 46199.022 | E22: Resolved | F22: Medium | G22: Email / Collaboration | H22: Marketing | I22: Chat | J22: A001 | K22: No | L22: 5 | M22: Riya Shah | N22: Workplace Support | O22: 4.2 | P22: Mumbai
A23: TKT-0022 | B23: 46142.964 | C23: 46143.098 | D23: 46144.359 | E23: Closed | F23: Low | G23: Printer / Peripheral | H23: Finance | I23: Portal | J23: A001 | K23: No | L23: 4 | M23: Riya Shah | N23: Workplace Support | O23: 4.2 | P23: Mumbai
A24: TKT-0023 | B24: 46145.485 | C24: 46145.497 | D24: 46145.605 | E24: Closed | F24: Critical | G24: Server / Connectivity | H24: Sales | I24: Chat | J24: A008 | K24: No | L24: 4 | M24: Dev Malhotra | N24: Network & Infra | O24: 3 | P24: Delhi
A25: TKT-0024 | B25: 46138.064 | C25: 46138.09 | D25: 46138.216 | E25: Closed | F25: High | G25: Password / Access | H25: Marketing | I25: Portal | J25: A011 | K25: No | L25: 5 | M25: Tanya Joshi | N25: Identity & Access | O25: 2.7 | P25: Delhi
... A44: TKT-0043 | B44: 46137.43 | C44: 46137.535 | D44: 46137.901 | E44: Closed | F44: Medium | G44: Password / Access | H44: Marketing | I44: Portal | J44: A011 | K44: No | L44: 5 | M44: Tanya Joshi | N44: Identity & Access | O44: 2.7 | P44: Delhi
A45: TKT-0044 | B45: 46174.065 | C45: 46174.153 | E45: Pending | F45: Medium | G45: Laptop / Hardware | H45: Marketing | I45: Email | J45: A001 | K45: No | M45: Riya Shah | N45: Workplace Support | O45: 4.2 | P45: Mumbai
A46: TKT-0045 | B46: 46181.972 | C46: 46182.388 | D46: 46185.579 | E46: Closed | F46: Low | G46: Laptop / Hardware | H46: Marketing | I46: Phone | J46: A001 | K46: No | L46: 4 | M46: Riya Shah | N46: Workplace Support | O46: 4.2 | P46: Mumbai
A47: TKT-0046 | B47: 46193.591 | C47: 46193.603 | D47: 46193.747 | E47: Closed | F47: Critical | G47: Password / Access | H47: Operations | I47: Portal | J47: A004 | K47: Yes | L47: 3 | M47: Neha Iyer | N47: Identity & Access | O47: 3.4 | P47: Bengaluru
A48: TKT-0047 | B48: 46137.642 | C48: 46137.65 | D48: 46137.712 | E48: Resolved | F48: Critical | G48: Password / Access | H48: Finance | I48: Email | J48: A011 | K48: No | L48: 5 | M48: Tanya Joshi | N48: Identity & Access | O48: 2.7 | P48: Delhi
A49: TKT-0048 | B49: 46192.389 | C49: 46192.4 | D49: 46192.527 | E49: Closed | F49: Critical | G49: ERP / Finance App | H49: Product | I49: Portal | J49: A006 | K49: No | L49: 5 | M49: Arjun Rao | N49: Business Apps | O49: 1.8 | P49: Hyderabad
A50: TKT-0049 | B50: 46137.839 | C50: 46138.033 | D50: 46141.044 | E50: Closed | F50: Low | G50: Laptop / Hardware | H50: Finance | I50: Portal | J50: A002 | K50: No | L50: 4 | M50: Kabir Mehta | N50: Workplace Support | O50: 2.1 | P50: Pune
A51: TKT-0050 | B51: 46203.401 | C51: 46203.729 | D51: 46204.221 | E51: Closed | F51: Low | G51: Laptop / Hardware | H51: Human Resources | I51: Chat | J51: A002 | K51: No | L51: 5 | M51: Kabir Mehta | N51: Workplace Support | O51: 2.1 | P51: Pune
A52: TKT-0051 | B52: 46124.738 | C52: 46124.771 | D52: 46124.989 | E52: Closed | F52: High | G52: CRM / Sales App | H52: Operations | I52: Portal | J52: A010 | K52: No | L52: 4 | M52: Rohan Sen | N52: Business Apps | O52: 4.8 | P52: Kolkata
A53: TKT-0052 | B53: 46126.587 | C53: 46126.75 | D53: 46128.196 | E53: Closed | F53: Medium | G53: Printer / Peripheral | H53: Legal | I53: Portal | J53: A002 | K53: No | L53: 4 | M53: Kabir Mehta | N53: Workplace Support | O53: 2.1 | P53: Pune
A54: TKT-0053 | B54: 46144.575 | C54: 46144.721 | D54: 46145.273 | E54: Resolved | F54: Low | G54: Printer / Peripheral | H54: Product | I54: Phone | J54: A001 | K54: No | L54: 4 | M54: Riya Shah | N54: Workplace Support | O54: 4.2 | P54: Mumbai
A55: TKT-0054 | B55: 46176.638 | C55: 46176.67 | D55: 46177.058 | E55: Closed | F55: High | G55: Server / Connectivity | H55: Sales | I55: Chat | J55: A007 | K55: Yes | L55: 3 | M55: Meera Nair | N55: Network & Infra | O55: 7.1 | P55: Pune
A56: TKT-0055 | B56: 46165.143 | C56: 46165.3 | D56: 46165.387 | E56: Closed | F56: Medium | G56: Email / Collaboration | H56: Engineering | I56: Portal | J56: A009 | K56: No | L56: 5 | M56: Ishita Bose | N56: Workplace Support | O56: 1.2 | P56: Kolkata
A57: TKT-0056 | B57: 46201.047 | C57: 46201.051 | D57: 46201.138 | E57: Closed | F57: Critical | G57: Password / Access | H57: Operations | I57: Portal | J57: A003 | K57: No | L57: 4 | M57: Aman Verma | N57: Identity & Access | O57: 5.6 | P57: Bengaluru
A58: TKT-0057 | B58: 46201.96 | C58: 46201.98 | D58: 46202.145 | E58: Closed | F58: High | G58: CRM / Sales App | H58: Operations | I58: Portal | J58: A010 | K58: No | L58: 4 | M58: Rohan Sen | N58: Business Apps | O58: 4.8 | P58: Kolkata
...

Sheet Clean_Tickets
A1: Ticket_ID | B1: Created_At | C1: First_Response_At | D1: Resolved_At | E1: Status | F1: Priority | G1: Issue_Category | H1: Department | I1: Channel | J1: Agent_ID | K1: Reopened | L1: CSAT_Score | M1: First_Response_Time | N1: Total_time | O1: Response_SLA_Target | P1: Resolution_SLA_Target | Q1: Response_SLA_Status | R1: Resolution_SLA_Status | S1: Agent_name | T1: Support_team | U1: Agent_exp | V1: Agent_location | W1: Duplicate
A2: TKT-0001 | B2: 46175.416 | C2: 46175.666 | E2: In Progress | F2: Medium | G2: Password / Access | H2: Marketing | I2: Phone | J2: A003 | K2: No | M2: =IF(OR(B2="",C2=""),"",24*(C2-B2)) -> 6.0145817 | N2: =IF(OR(B2="",D2=""),"",24*(D2-B2)) | O2: =VLOOKUP(F2,SLA_Targets!$A$2:$C$5,2,FALSE) -> 4 | P2: =VLOOKUP(F2,SLA_Targets!$A$2:$C$5,3,FALSE) -> 24 | Q2: =IF(M2="","Pending",IF(M2<=O2,"Met","Breached")) -> Breached | R2: =IF(N2="","Pending",IF(N2<=P2,"Met","Breached")) -> Pending | S2: Aman Verma | T2: Identity & Access | U2: 5.6 | V2: Bengaluru | W2: =COUNTIF($A$2:$A$321,A2) -> 1
A3: TKT-0002 | B3: 46135.922 | C3: 46135.938 | D3: 46136.028 | E3: Resolved | F3: Critical | G3: ERP / Finance App | H3: Product | I3: Portal | J3: A005 | K3: No | L3: 4 | M3: =IF(OR(B3="",C3=""),"",24*(C3-B3)) -> 0.36243667 | N3: =IF(OR(B3="",D3=""),"",24*(D3-B3)) -> 2.5420247 | O3: =VLOOKUP(F3,SLA_Targets!$A$2:$C$5,2,FALSE) -> 0.5 | P3: =VLOOKUP(F3,SLA_Targets!$A$2:$C$5,3,FALSE) -> 4 | Q3: =IF(M3="","Pending",IF(M3<=O3,"Met","Breached")) -> Met | R3: =IF(N3="","Pending",IF(N3<=P3,"Met","Breached")) -> Met | S3: Sana Khan | T3: Business Apps | U3: 6.3 | V3: Mumbai | W3: =COUNTIF($A$2:$A$321,A3) -> 1
A4: TKT-0003 | B4: 46146.728 | C4: 46146.814 | D4: 46148.227 | E4: Closed | F4: Medium | G4: CRM / Sales App | H4: Engineering | I4: Portal | J4: A010 | K4: No | L4: 4 | M4: =IF(OR(B4="",C4=""),"",24*(C4-B4)) -> 2.0588322 | N4: =IF(OR(B4="",D4=""),"",24*(D4-B4)) -> 35.982996 | O4: =VLOOKUP(F4,SLA_Targets!$A$2:$C$5,2,FALSE) -> 4 | P4: =VLOOKUP(F4,SLA_Targets!$A$2:$C$5,3,FALSE) -> 24 | Q4: =IF(M4="","Pending",IF(M4<=O4,"Met","Breached")) -> Met | R4: =IF(N4="","Pending",IF(N4<=P4,"Met","Breached")) -> Breached | S4: Rohan Sen | T4: Business Apps | U4: 4.8 | V4: Kolkata | W4: =COUNTIF($A$2:$A$321,A4) -> 1
A5: TKT-0004 | B5: 46188.391 | C5: 46188.408 | D5: 46188.517 | E5: Resolved | F5: Critical | G5: Laptop / Hardware | H5: Human Resources | I5: Portal | J5: A001 | K5: No | L5: 4 | M5: =IF(OR(B5="",C5=""),"",24*(C5-B5)) -> 0.42208333 | N5: =IF(OR(B5="",D5=""),"",24*(D5-B5)) -> 3.0318511 | O5: =VLOOKUP(F5,SLA_Targets!$A$2:$C$5,2,FALSE) -> 0.5 | P5: =VLOOKUP(F5,SLA_Targets!$A$2:$C$5,3,FALSE) -> 4 | Q5: =IF(M5="","Pending",IF(M5<=O5,"Met","Breached")) -> Met | R5: =IF(N5="","Pending",IF(N5<=P5,"Met","Breached")) -> Met | S5: Riya Shah | T5: Workplace Support | U5: 4.2 | V5: Mumbai | W5: =COUNTIF($A$2:$A$321,A5) -> 1
A6: TKT-0005 | B6: 46184.125 | C6: 46184.248 | D6: 46186.192 | E6: Closed | F6: Medium | G6: Laptop / Hardware | H6: Marketing | I6: Portal | J6: A002 | K6: No | L6: 3 | M6: =IF(OR(B6="",C6=""),"",24*(C6-B6)) -> 2.9563756 | N6: =IF(OR(B6="",D6=""),"",24*(D6-B6)) -> 49.616841 | O6: =VLOOKUP(F6,SLA_Targets!$A$2:$C$5,2,FALSE) -> 4 | P6: =VLOOKUP(F6,SLA_Targets!$A$2:$C$5,3,FALSE) -> 24 | Q6: =IF(M6="","Pending",IF(M6<=O6,"Met","Breached")) -> Met | R6: =IF(N6="","Pending",IF(N6<=P6,"Met","Breached")) -> Breached | S6: Kabir Mehta | T6: Workplace Support | U6: 2.1 | V6: Pune | W6: =COUNTIF($A$2:$A$321,A6) -> 1
A7: TKT-0006 | B7: 46199.228 | C7: 46199.276 | D7: 46199.51 | E7: Resolved | F7: High | G7: Server / Connectivity | H7: Sales | I7: Phone | J7: A008 | K7: Yes | L7: 2 | M7: =IF(OR(B7="",C7=""),"",24*(C7-B7)) -> 1.1522967 | N7: =IF(OR(B7="",D7=""),"",24*(D7-B7)) -> 6.7813256 | O7: =VLOOKUP(F7,SLA_Targets!$A$2:$C$5,2,FALSE) -> 1 | P7: =VLOOKUP(F7,SLA_Targets!$A$2:$C$5,3,FALSE) -> 8 | Q7: =IF(M7="","Pending",IF(M7<=O7,"Met","Breached")) -> Breached | R7: =IF(N7="","Pending",IF(N7<=P7,"Met","Breached")) -> Met | S7: Dev Malhotra | T7: Network & Infra | U7: 3 | V7: Delhi | W7: =COUNTIF($A$2:$A$321,A7) -> 1
A8: TKT-0007 | B8: 46196.938 | C8: 46196.982 | D8: 46197.225 | E8: Closed | F8: High | G8: Password / Access | H8: Product | I8: Portal | J8: A011 | K8: No | L8: 4 | M8: =IF(OR(B8="",C8=""),"",24*(C8-B8)) -> 1.042355 | N8: =IF(OR(B8="",D8=""),"",24*(D8-B8)) -> 6.8776336 | O8: =VLOOKUP(F8,SLA_Targets!$A$2:$C$5,2,FALSE) -> 1 | P8: =VLOOKUP(F8,SLA_Targets!$A$2:$C$5,3,FALSE) -> 8 | Q8: =IF(M8="","Pending",IF(M8<=O8,"Met","Breached")) -> Breached | R8: =IF(N8="","Pending",IF(N8<=P8,"Met","Breached")) -> Met | S8: Tanya Joshi | T8: Identity & Access | U8: 2.7 | V8: Delhi | W8: =COUNTIF($A$2:$A$321,A8) -> 1
A9: TKT-0008 | B9: 46124.164 | C9: 46124.179 | D9: 46124.693 | E9: Closed | F9: High | G9: Laptop / Hardware | H9: Operations | I9: Email | J9: A001 | K9: No | L9: 5 | M9: =IF(OR(B9="",C9=""),"",24*(C9-B9)) -> 0.35369556 | N9: =IF(OR(B9="",D9=""),"",24*(D9-B9)) -> 12.703308 | O9: =VLOOKUP(F9,SLA_Targets!$A$2:$C$5,2,FALSE) -> 1 | P9: =VLOOKUP(F9,SLA_Targets!$A$2:$C$5,3,FALSE) -> 8 | Q9: =IF(M9="","Pending",IF(M9<=O9,"Met","Breached")) -> Met | R9: =IF(N9="","Pending",IF(N9<=P9,"Met","Breached")) -> Breached | S9: Riya Shah | T9: Workplace Support | U9: 4.2 | V9: Mumbai | W9: =COUNTIF($A$2:$A$321,A9) -> 1
A10: TKT-0009 | B10: 46202.51 | C10: 46202.522 | D10: 46202.589 | E10: Resolved | F10: Critical | G10: Password / Access | H10: Human Resources | I10: Phone | J10: A003 | K10: No | L10: 4 | M10: =IF(OR(B10="",C10=""),"",24*(C10-B10)) -> 0.2844575 | N10: =IF(OR(B10="",D10=""),"",24*(D10-B10)) -> 1.8904608 | O10: =VLOOKUP(F10,SLA_Targets!$A$2:$C$5,2,FALSE) -> 0.5 | P10: =VLOOKUP(F10,SLA_Targets!$A$2:$C$5,3,FALSE) -> 4 | Q10: =IF(M10="","Pending",IF(M10<=O10,"Met","Breached")) -> Met | R10: =IF(N10="","Pending",IF(N10<=P10,"Met","Breached")) -> Met | S10: Aman Verma | T10: Identity & Access | U10: 5.6 | V10: Bengaluru | W10: =COUNTIF($A$2:$A$321,A10) -> 1
A11: TKT-0010 | B11: 46159.479 | C11: 46159.508 | D11: 46159.69 | E11: Closed | F11: Critical | G11: Server / Connectivity | H11: Product | I11: Chat | J11: A012 | K11: No | L11: 3 | M11: =IF(OR(B11="",C11=""),"",24*(C11-B11)) -> 0.71393806 | N11: =IF(OR(B11="",D11=""),"",24*(D11-B11)) -> 5.0640642 | O11: =VLOOKUP(F11,SLA_Targets!$A$2:$C$5,2,FALSE) -> 0.5 | P11: =VLOOKUP(F11,SLA_Targets!$A$2:$C$5,3,FALSE) -> 4 | Q11: =IF(M11="","Pending",IF(M11<=O11,"Met","Breached")) -> Breached | R11: =IF(N11="","Pending",IF(N11<=P11,"Met","Breached")) -> Breached | S11: Vikram Pillai | T11: Network & Infra | U11: 5.1 | V11: Hyderabad | W11: =COUNTIF($A$2:$A$321,A11) -> 1
A12: TKT-0011 | B12: 46119.55 | C12: 46119.653 | D12: 46119.88 | E12: Closed | F12: Medium | G12: Email / Collaboration | H12: Marketing | I12: Portal | J12: A001 | K12: No | L12: 5 | M12: =IF(OR(B12="",C12=""),"",24*(C12-B12)) -> 2.4846203 | N12: =IF(OR(B12="",D12=""),"",24*(D12-B12)) -> 7.9351642 | O12: =VLOOKUP(F12,SLA_Targets!$A$2:$C$5,2,FALSE) -> 4 | P12: =VLOOKUP(F12,SLA_Targets!$A$2:$C$5,3,FALSE) -> 24 | Q12: =IF(M12="","Pending",IF(M12<=O12,"Met","Breached")) -> Met | R12: =IF(N12="","Pending",IF(N12<=P12,"Met","Breached")) -> Met | S12: Riya Shah | T12: Workplace Support | U12: 4.2 | V12: Mumbai | W12: =COUNTIF($A$2:$A$321,A12) -> 1
A13: TKT-0012 | B13: 46199.004 | C13: 46199.18 | E13: In Progress | F13: Medium | G13: CRM / Sales App | H13: Product | I13: Portal | J13: A006 | K13: No | M13: =IF(OR(B13="",C13=""),"",24*(C13-B13)) -> 4.225435 | N13: =IF(OR(B13="",D13=""),"",24*(D13-B13)) | O13: =VLOOKUP(F13,SLA_Targets!$A$2:$C$5,2,FALSE) -> 4 | P13: =VLOOKUP(F13,SLA_Targets!$A$2:$C$5,3,FALSE) -> 24 | Q13: =IF(M13="","Pending",IF(M13<=O13,"Met","Breached")) -> Breached | R13: =IF(N13="","Pending",IF(N13<=P13,"Met","Breached")) -> Pending | S13: Arjun Rao | T13: Business Apps | U13: 1.8 | V13: Hyderabad | W13: =COUNTIF($A$2:$A$321,A13) -> 1
A14: TKT-0013 | B14: 46119.218 | C14: 46119.302 | D14: 46119.644 | E14: Closed | F14: Medium | G14: Email / Collaboration | H14: Marketing | I14: Portal | J14: A001 | K14: No | L14: 4 | M14: =IF(OR(B14="",C14=""),"",24*(C14-B14)) -> 2.0075497 | N14: =IF(OR(B14="",D14=""),"",24*(D14-B14)) -> 10.218088 | O14: =VLOOKUP(F14,SLA_Targets!$A$2:$C$5,2,FALSE) -> 4 | P14: =VLOOKUP(F14,SLA_Targets!$A$2:$C$5,3,FALSE) -> 24 | Q14: =IF(M14="","Pending",IF(M14<=O14,"Met","Breached")) -> Met | R14: =IF(N14="","Pending",IF(N14<=P14,"Met","Breached")) -> Met | S14: Riya Shah | T14: Workplace Support | U14: 4.2 | V14: Mumbai | W14: =COUNTIF($A$2:$A$321,A14) -> 1
A15: TKT-0014 | B15: 46165.819 | C15: 46165.929 | D15: 46166.299 | E15: Closed | F15: Low | G15: Printer / Peripheral | H15: Sales | I15: Email | J15: A001 | K15: No | L15: 5 | M15: =IF(OR(B15="",C15=""),"",24*(C15-B15)) -> 2.6311858 | N15: =IF(OR(B15="",D15=""),"",24*(D15-B15)) -> 11.506821 | O15: =VLOOKUP(F15,SLA_Targets!$A$2:$C$5,2,FALSE) -> 8 | P15: =VLOOKUP(F15,SLA_Targets!$A$2:$C$5,3,FALSE) -> 48 | Q15: =IF(M15="","Pending",IF(M15<=O15,"Met","Breached")) -> Met | R15: =IF(N15="","Pending",IF(N15<=P15,"Met","Breached")) -> Met | S15: Riya Shah | T15: Workplace Support | U15: 4.2 | V15: Mumbai | W15: =COUNTIF($A$2:$A$321,A15) -> 1
A16: TKT-0015 | B16: 46157.51 | C16: 46157.69 | D16: 46158.271 | E16: Resolved | F16: Medium | G16: Laptop / Hardware | H16: Engineering | I16: Portal | J16: A009 | K16: No | L16: 4 | M16: =IF(OR(B16="",C16=""),"",24*(C16-B16)) -> 4.3204553 | N16: =IF(OR(B16="",D16=""),"",24*(D16-B16)) -> 18.248212 | O16: =VLOOKUP(F16,SLA_Targets!$A$2:$C$5,2,FALSE) -> 4 | P16: =VLOOKUP(F16,SLA_Targets!$A$2:$C$5,3,FALSE) -> 24 | Q16: =IF(M16="","Pending",IF(M16<=O16,"Met","Breached")) -> Breached | R16: =IF(N16="","Pending",IF(N16<=P16,"Met","Breached")) -> Met | S16: Ishita Bose | T16: Workplace Support | U16: 1.2 | V16: Kolkata | W16: =COUNTIF($A$2:$A$321,A16) -> 1
A17: TKT-0016 | B17: 46195.99 | C17: 46196.255 | D17: 46197.355 | E17: Closed | F17: Medium | G17: Laptop / Hardware | H17: Marketing | I17: Portal | J17: A009 | K17: No | L17: 4 | M17: =IF(OR(B17="",C17=""),"",24*(C17-B17)) -> 6.3503839 | N17: =IF(OR(B17="",D17=""),"",24*(D17-B17)) -> 32.754711 | O17: =VLOOKUP(F17,SLA_Targets!$A$2:$C$5,2,FALSE) -> 4 | P17: =VLOOKUP(F17,SLA_Targets!$A$2:$C$5,3,FALSE) -> 24 | Q17: =IF(M17="","Pending",IF(M17<=O17,"Met","Breached")) -> Breached | R17: =IF(N17="","Pending",IF(N17<=P17,"Met","Breached")) -> Breached | S17: Ishita Bose | T17: Workplace Support | U17: 1.2 | V17: Kolkata | W17: =COUNTIF($A$2:$A$321,A17) -> 1
A18: TKT-0017 | B18: 46138.651 | C18: 46138.801 | D18: 46139.452 | E18: Closed | F18: Medium | G18: Laptop / Hardware | H18: Operations | I18: Portal | J18: A001 | K18: No | L18: 4 | M18: =IF(OR(B18="",C18=""),"",24*(C18-B18)) -> 3.5913631 | N18: =IF(OR(B18="",D18=""),"",24*(D18-B18)) -> 19.228846 | O18: =VLOOKUP(F18,SLA_Targets!$A$2:$C$5,2,FALSE) -> 4 | P18: =VLOOKUP(F18,SLA_Targets!$A$2:$C$5,3,FALSE) -> 24 | Q18: =IF(M18="","Pending",IF(M18<=O18,"Met","Breached")) -> Met | R18: =IF(N18="","Pending",IF(N18<=P18,"Met","Breached")) -> Met | S18: Riya Shah | T18: Workplace Support | U18: 4.2 | V18: Mumbai | W18: =COUNTIF($A$2:$A$321,A18) -> 1
A19: TKT-0018 | B19: 46137.051 | C19: 46137.113 | D19: 46137.381 | E19: Closed | F19: High | G19: Email / Collaboration | H19: Operations | I19: Email | J19: A009 | K19: No | L19: 4 | M19: =IF(OR(B19="",C19=""),"",24*(C19-B19)) -> 1.48537 | N19: =IF(OR(B19="",D19=""),"",24*(D19-B19)) -> 7.9174425 | O19: =VLOOKUP(F19,SLA_Targets!$A$2:$C$5,2,FALSE) -> 1 | P19: =VLOOKUP(F19,SLA_Targets!$A$2:$C$5,3,FALSE) -> 8 | Q19: =IF(M19="","Pending",IF(M19<=O19,"Met","Breached")) -> Breached | R19: =IF(N19="","Pending",IF(N19<=P19,"Met","Breached")) -> Met | S19: Ishita Bose | T19: Workplace Support | U19: 1.2 | V19: Kolkata | W19: =COUNTIF($A$2:$A$321,A19) -> 1
A20: TKT-0019 | B20: 46180.083 | C20: 46180.121 | D20: 46180.475 | E20: Closed | F20: High | G20: CRM / Sales App | H20: Operations | I20: Portal | J20: A006 | K20: No | L20: 4 | M20: =IF(OR(B20="",C20=""),"",24*(C20-B20)) -> 0.9224025 | N20: =IF(OR(B20="",D20=""),"",24*(D20-B20)) -> 9.4210236 | O20: =VLOOKUP(F20,SLA_Targets!$A$2:$C$5,2,FALSE) -> 1 | P20: =VLOOKUP(F20,SLA_Targets!$A$2:$C$5,3,FALSE) -> 8 | Q20: =IF(M20="","Pending",IF(M20<=O20,"Met","Breached")) -> Met | R20: =IF(N20="","Pending",IF(N20<=P20,"Met","Breached")) -> Breached | S20: Arjun Rao | T20: Business Apps | U20: 1.8 | V20: Hyderabad | W20: =COUNTIF($A$2:$A$321,A20) -> 1
A21: TKT-0020 | B21: 46199.074 | C21: 46199.084 | D21: 46199.144 | E21: Closed | F21: Critical | G21: VPN / Network | H21: Legal | I21: Email | J21: A007 | K21: No | L21: 5 | M21: =IF(OR(B21="",C21=""),"",24*(C21-B21)) -> 0.238185 | N21: =IF(OR(B21="",D21=""),"",24*(D21-B21)) -> 1.6590339 | O21: =VLOOKUP(F21,SLA_Targets!$A$2:$C$5,2,FALSE) -> 0.5 | P21: =VLOOKUP(F21,SLA_Targets!$A$2:$C$5,3,FALSE) -> 4 | Q21: =IF(M21="","Pending",IF(M21<=O21,"Met","Breached")) -> Met | R21: =IF(N21="","Pending",IF(N21<=P21,"Met","Breached")) -> Met | S21: Meera Nair | T21: Network & Infra | U21: 7.1 | V21: Pune | W21: =COUNTIF($A$2:$A$321,A21) -> 1
A22: TKT-0021 | B22: 46198.26 | C22: 46198.387 | D22: 46199.022 | E22: Resolved | F22: Medium | G22: Email / Collaboration | H22: Marketing | I22: Chat | J22: A001 | K22: No | L22: 5 | M22: =IF(OR(B22="",C22=""),"",24*(C22-B22)) -> 3.0621336 | N22: =IF(OR(B22="",D22=""),"",24*(D22-B22)) -> 18.296348 | O22: =VLOOKUP(F22,SLA_Targets!$A$2:$C$5,2,FALSE) -> 4 | P22: =VLOOKUP(F22,SLA_Targets!$A$2:$C$5,3,FALSE) -> 24 | Q22: =IF(M22="","Pending",IF(M22<=O22,"Met","Breached")) -> Met | R22: =IF(N22="","Pending",IF(N22<=P22,"Met","Breached")) -> Met | S22: Riya Shah | T22: Workplace Support | U22: 4.2 | V22: Mumbai | W22: =COUNTIF($A$2:$A$321,A22) -> 1
A23: TKT-0022 | B23: 46142.964 | C23: 46143.098 | D23: 46144.359 | E23: Closed | F23: Low | G23: Printer / Peripheral | H23: Finance | I23: Portal | J23: A001 | K23: No | L23: 4 | M23: =IF(OR(B23="",C23=""),"",24*(C23-B23)) -> 3.2061353 | N23: =IF(OR(B23="",D23=""),"",24*(D23-B23)) -> 33.480969 | O23: =VLOOKUP(F23,SLA_Targets!$A$2:$C$5,2,FALSE) -> 8 | P23: =VLOOKUP(F23,SLA_Targets!$A$2:$C$5,3,FALSE) -> 48 | Q23: =IF(M23="","Pending",IF(M23<=O23,"Met","Breached")) -> Met | R23: =IF(N23="","Pending",IF(N23<=P23,"Met","Breached")) -> Met | S23: Riya Shah | T23: Workplace Support | U23: 4.2 | V23: Mumbai | W23: =COUNTIF($A$2:$A$321,A23) -> 1
A24: TKT-0023 | B24: 46145.485 | C24: 46145.497 | D24: 46145.605 | E24: Closed | F24: Critical | G24: Server / Connectivity | H24: Sales | I24: Chat | J24: A008 | K24: No | L24: 4 | M24: =IF(OR(B24="",C24=""),"",24*(C24-B24)) -> 0.29190139 | N24: =IF(OR(B24="",D24=""),"",24*(D24-B24)) -> 2.8875456 | O24: =VLOOKUP(F24,SLA_Targets!$A$2:$C$5,2,FALSE) -> 0.5 | P24: =VLOOKUP(F24,SLA_Targets!$A$2:$C$5,3,FALSE) -> 4 | Q24: =IF(M24="","Pending",IF(M24<=O24,"Met","Breached")) -> Met | R24: =IF(N24="","Pending",IF(N24<=P24,"Met","Breached")) -> Met | S24: Dev Malhotra | T24: Network & Infra | U24: 3 | V24: Delhi | W24: =COUNTIF($A$2:$A$321,A24) -> 1
A25: TKT-0024 | B25: 46138.064 | C25: 46138.09 | D25: 46138.216 | E25: Closed | F25: High | G25: Password / Access | H25: Marketing | I25: Portal | J25: A011 | K25: No | L25: 5 | M25: =IF(OR(B25="",C25=""),"",24*(C25-B25)) -> 0.61496889 | N25: =IF(OR(B25="",D25=""),"",24*(D25-B25)) -> 3.6478572 | O25: =VLOOKUP(F25,SLA_Targets!$A$2:$C$5,2,FALSE) -> 1 | P25: =VLOOKUP(F25,SLA_Targets!$A$2:$C$5,3,FALSE) -> 8 | Q25: =IF(M25="","Pending",IF(M25<=O25,"Met","Breached")) -> Met | R25: =IF(N25="","Pending",IF(N25<=P25,"Met","Breached")) -> Met | S25: Tanya Joshi | T25: Identity & Access | U25: 2.7 | V25: Delhi | W25: =COUNTIF($A$2:$A$321,A25) -> 1
... A44: TKT-0043 | B44: 46137.43 | C44: 46137.535 | D44: 46137.901 | E44: Closed | F44: Medium | G44: Password / Access | H44: Marketing | I44: Portal | J44: A011 | K44: No | L44: 5 | M44: =IF(OR(B44="",C44=""),"",24*(C44-B44)) -> 2.5178983 | N44: =IF(OR(B44="",D44=""),"",24*(D44-B44)) -> 11.285353 | O44: =VLOOKUP(F44,SLA_Targets!$A$2:$C$5,2,FALSE) -> 4 | P44: =VLOOKUP(F44,SLA_Targets!$A$2:$C$5,3,FALSE) -> 24 | Q44: =IF(M44="","Pending",IF(M44<=O44,"Met","Breached")) -> Met | R44: =IF(N44="","Pending",IF(N44<=P44,"Met","Breached")) -> Met | S44: Tanya Joshi | T44: Identity & Access | U44: 2.7 | V44: Delhi | W44: =COUNTIF($A$2:$A$321,A44) -> 1
A45: TKT-0044 | B45: 46174.065 | C45: 46174.153 | E45: Pending | F45: Medium | G45: Laptop / Hardware | H45: Marketing | I45: Email | J45: A001 | K45: No | M45: =IF(OR(B45="",C45=""),"",24*(C45-B45)) -> 2.1067244 | N45: =IF(OR(B45="",D45=""),"",24*(D45-B45)) | O45: =VLOOKUP(F45,SLA_Targets!$A$2:$C$5,2,FALSE) -> 4 | P45: =VLOOKUP(F45,SLA_Targets!$A$2:$C$5,3,FALSE) -> 24 | Q45: =IF(M45="","Pending",IF(M45<=O45,"Met","Breached")) -> Met | R45: =IF(N45="","Pending",IF(N45<=P45,"Met","Breached")) -> Pending | S45: Riya Shah | T45: Workplace Support | U45: 4.2 | V45: Mumbai | W45: =COUNTIF($A$2:$A$321,A45) -> 1
A46: TKT-0045 | B46: 46181.972 | C46: 46182.388 | D46: 46185.579 | E46: Closed | F46: Low | G46: Laptop / Hardware | H46: Marketing | I46: Phone | J46: A001 | K46: No | L46: 4 | M46: =IF(OR(B46="",C46=""),"",24*(C46-B46)) -> 9.9785008 | N46: =IF(OR(B46="",D46=""),"",24*(D46-B46)) -> 86.55925 | O46: =VLOOKUP(F46,SLA_Targets!$A$2:$C$5,2,FALSE) -> 8 | P46: =VLOOKUP(F46,SLA_Targets!$A$2:$C$5,3,FALSE) -> 48 | Q46: =IF(M46="","Pending",IF(M46<=O46,"Met","Breached")) -> Breached | R46: =IF(N46="","Pending",IF(N46<=P46,"Met","Breached")) -> Breached | S46: Riya Shah | T46: Workplace Support | U46: 4.2 | V46: Mumbai | W46: =COUNTIF($A$2:$A$321,A46) -> 1
A47: TKT-0046 | B47: 46193.591 | C47: 46193.603 | D47: 46193.747 | E47: Closed | F47: Critical | G47: Password / Access | H47: Operations | I47: Portal | J47: A004 | K47: Yes | L47: 3 | M47: =IF(OR(B47="",C47=""),"",24*(C47-B47)) -> 0.27262833 | N47: =IF(OR(B47="",D47=""),"",24*(D47-B47)) -> 3.7496522 | O47: =VLOOKUP(F47,SLA_Targets!$A$2:$C$5,2,FALSE) -> 0.5 | P47: =VLOOKUP(F47,SLA_Targets!$A$2:$C$5,3,FALSE) -> 4 | Q47: =IF(M47="","Pending",IF(M47<=O47,"Met","Breached")) -> Met | R47: =IF(N47="","Pending",IF(N47<=P47,"Met","Breached")) -> Met | S47: Neha Iyer | T47: Identity & Access | U47: 3.4 | V47: Bengaluru | W47: =COUNTIF($A$2:$A$321,A47) -> 1
A48: TKT-0047 | B48: 46137.642 | C48: 46137.65 | D48: 46137.712 | E48: Resolved | F48: Critical | G48: Password / Access | H48: Finance | I48: Email | J48: A011 | K48: No | L48: 5 | M48: =IF(OR(B48="",C48=""),"",24*(C48-B48)) -> 0.21131583 | N48: =IF(OR(B48="",D48=""),"",24*(D48-B48)) -> 1.6779747 | O48: =VLOOKUP(F48,SLA_Targets!$A$2:$C$5,2,FALSE) -> 0.5 | P48: =VLOOKUP(F48,SLA_Targets!$A$2:$C$5,3,FALSE) -> 4 | Q48: =IF(M48="","Pending",IF(M48<=O48,"Met","Breached")) -> Met | R48: =IF(N48="","Pending",IF(N48<=P48,"Met","Breached")) -> Met | S48: Tanya Joshi | T48: Identity & Access | U48: 2.7 | V48: Delhi | W48: =COUNTIF($A$2:$A$321,A48) -> 1
A49: TKT-0048 | B49: 46192.389 | C49: 46192.4 | D49: 46192.527 | E49: Closed | F49: Critical | G49: ERP / Finance App | H49: Product | I49: Portal | J49: A006 | K49: No | L49: 5 | M49: =IF(OR(B49="",C49=""),"",24*(C49-B49)) -> 0.26500667 | N49: =IF(OR(B49="",D49=""),"",24*(D49-B49)) -> 3.3113047 | O49: =VLOOKUP(F49,SLA_Targets!$A$2:$C$5,2,FALSE) -> 0.5 | P49: =VLOOKUP(F49,SLA_Targets!$A$2:$C$5,3,FALSE) -> 4 | Q49: =IF(M49="","Pending",IF(M49<=O49,"Met","Breached")) -> Met | R49: =IF(N49="","Pending",IF(N49<=P49,"Met","Breached")) -> Met | S49: Arjun Rao | T49: Business Apps | U49: 1.8 | V49: Hyderabad | W49: =COUNTIF($A$2:$A$321,A49) -> 1
A50: TKT-0049 | B50: 46137.839 | C50: 46138.033 | D50: 46141.044 | E50: Closed | F50: Low | G50: Laptop / Hardware | H50: Finance | I50: Portal | J50: A002 | K50: No | L50: 4 | M50: =IF(OR(B50="",C50=""),"",24*(C50-B50)) -> 4.6702731 | N50: =IF(OR(B50="",D50=""),"",24*(D50-B50)) -> 76.921868 | O50: =VLOOKUP(F50,SLA_Targets!$A$2:$C$5,2,FALSE) -> 8 | P50: =VLOOKUP(F50,SLA_Targets!$A$2:$C$5,3,FALSE) -> 48 | Q50: =IF(M50="","Pending",IF(M50<=O50,"Met","Breached")) -> Met | R50: =IF(N50="","Pending",IF(N50<=P50,"Met","Breached")) -> Breached | S50: Kabir Mehta | T50: Workplace Support | U50: 2.1 | V50: Pune | W50: =COUNTIF($A$2:$A$321,A50) -> 1
A51: TKT-0050 | B51: 46203.401 | C51: 46203.729 | D51: 46204.221 | E51: Closed | F51: Low | G51: Laptop / Hardware | H51: Human Resources | I51: Chat | J51: A002 | K51: No | L51: 5 | M51: =IF(OR(B51="",C51=""),"",24*(C51-B51)) -> 7.8629464 | N51: =IF(OR(B51="",D51=""),"",24*(D51-B51)) -> 19.672307 | O51: =VLOOKUP(F51,SLA_Targets!$A$2:$C$5,2,FALSE) -> 8 | P51: =VLOOKUP(F51,SLA_Targets!$A$2:$C$5,3,FALSE) -> 48 | Q51: =IF(M51="","Pending",IF(M51<=O51,"Met","Breached")) -> Met | R51: =IF(N51="","Pending",IF(N51<=P51,"Met","Breached")) -> Met | S51: Kabir Mehta | T51: Workplace Support | U51: 2.1 | V51: Pune | W51: =COUNTIF($A$2:$A$321,A51) -> 1
A52: TKT-0051 | B52: 46124.738 | C52: 46124.771 | D52: 46124.989 | E52: Closed | F52: High | G52: CRM / Sales App | H52: Operations | I52: Portal | J52: A010 | K52: No | L52: 4 | M52: =IF(OR(B52="",C52=""),"",24*(C52-B52)) -> 0.78331722 | N52: =IF(OR(B52="",D52=""),"",24*(D52-B52)) -> 6.0305694 | O52: =VLOOKUP(F52,SLA_Targets!$A$2:$C$5,2,FALSE) -> 1 | P52: =VLOOKUP(F52,SLA_Targets!$A$2:$C$5,3,FALSE) -> 8 | Q52: =IF(M52="","Pending",IF(M52<=O52,"Met","Breached")) -> Met | R52: =IF(N52="","Pending",IF(N52<=P52,"Met","Breached")) -> Met | S52: Rohan Sen | T52: Business Apps | U52: 4.8 | V52: Kolkata | W52: =COUNTIF($A$2:$A$321,A52) -> 1
A53: TKT-0052 | B53: 46126.587 | C53: 46126.75 | D53: 46128.196 | E53: Closed | F53: Medium | G53: Printer / Peripheral | H53: Legal | I53: Portal | J53: A002 | K53: No | L53: 4 | M53: =IF(OR(B53="",C53=""),"",24*(C53-B53)) -> 3.9065358 | N53: =IF(OR(B53="",D53=""),"",24*(D53-B53)) -> 38.617853 | O53: =VLOOKUP(F53,SLA_Targets!$A$2:$C$5,2,FALSE) -> 4 | P53: =VLOOKUP(F53,SLA_Targets!$A$2:$C$5,3,FALSE) -> 24 | Q53: =IF(M53="","Pending",IF(M53<=O53,"Met","Breached")) -> Met | R53: =IF(N53="","Pending",IF(N53<=P53,"Met","Breached")) -> Breached | S53: Kabir Mehta | T53: Workplace Support | U53: 2.1 | V53: Pune | W53: =COUNTIF($A$2:$A$321,A53) -> 1
A54: TKT-0053 | B54: 46144.575 | C54: 46144.721 | D54: 46145.273 | E54: Resolved | F54: Low | G54: Printer / Peripheral | H54: Product | I54: Phone | J54: A001 | K54: No | L54: 4 | M54: =IF(OR(B54="",C54=""),"",24*(C54-B54)) -> 3.5015917 | N54: =IF(OR(B54="",D54=""),"",24*(D54-B54)) -> 16.759723 | O54: =VLOOKUP(F54,SLA_Targets!$A$2:$C$5,2,FALSE) -> 8 | P54: =VLOOKUP(F54,SLA_Targets!$A$2:$C$5,3,FALSE) -> 48 | Q54: =IF(M54="","Pending",IF(M54<=O54,"Met","Breached")) -> Met | R54: =IF(N54="","Pending",IF(N54<=P54,"Met","Breached")) -> Met | S54: Riya Shah | T54: Workplace Support | U54: 4.2 | V54: Mumbai | W54: =COUNTIF($A$2:$A$321,A54) -> 1
A55: TKT-0054 | B55: 46176.638 | C55: 46176.67 | D55: 46177.058 | E55: Closed | F55: High | G55: Server / Connectivity | H55: Sales | I55: Chat | J55: A007 | K55: Yes | L55: 3 | M55: =IF(OR(B55="",C55=""),"",24*(C55-B55)) -> 0.765885 | N55: =IF(OR(B55="",D55=""),"",24*(D55-B55)) -> 10.073331 | O55: =VLOOKUP(F55,SLA_Targets!$A$2:$C$5,2,FALSE) -> 1 | P55: =VLOOKUP(F55,SLA_Targets!$A$2:$C$5,3,FALSE) -> 8 | Q55: =IF(M55="","Pending",IF(M55<=O55,"Met","Breached")) -> Met | R55: =IF(N55="","Pending",IF(N55<=P55,"Met","Breached")) -> Breached | S55: Meera Nair | T55: Network & Infra | U55: 7.1 | V55: Pune | W55: =COUNTIF($A$2:$A$321,A55) -> 1
A56: TKT-0055 | B56: 46165.143 | C56: 46165.3 | D56: 46165.387 | E56: Closed | F56: Medium | G56: Email / Collaboration | H56: Engineering | I56: Portal | J56: A009 | K56: No | L56: 5 | M56: =IF(OR(B56="",C56=""),"",24*(C56-B56)) -> 3.77331 | N56: =IF(OR(B56="",D56=""),"",24*(D56-B56)) -> 5.8535489 | O56: =VLOOKUP(F56,SLA_Targets!$A$2:$C$5,2,FALSE) -> 4 | P56: =VLOOKUP(F56,SLA_Targets!$A$2:$C$5,3,FALSE) -> 24 | Q56: =IF(M56="","Pending",IF(M56<=O56,"Met","Breached")) -> Met | R56: =IF(N56="","Pending",IF(N56<=P56,"Met","Breached")) -> Met | S56: Ishita Bose | T56: Workplace Support | U56: 1.2 | V56: Kolkata | W56: =COUNTIF($A$2:$A$321,A56) -> 1
A57: TKT-0056 | B57: 46201.047 | C57: 46201.051 | D57: 46201.138 | E57: Closed | F57: Critical | G57: Password / Access | H57: Operations | I57: Portal | J57: A003 | K57: No | L57: 4 | M57: =IF(OR(B57="",C57=""),"",24*(C57-B57)) -> 0.087196111 | N57: =IF(OR(B57="",D57=""),"",24*(D57-B57)) -> 2.1931147 | O57: =VLOOKUP(F57,SLA_Targets!$A$2:$C$5,2,FALSE) -> 0.5 | P57: =VLOOKUP(F57,SLA_Targets!$A$2:$C$5,3,FALSE) -> 4 | Q57: =IF(M57="","Pending",IF(M57<=O57,"Met","Breached")) -> Met | R57: =IF(N57="","Pending",IF(N57<=P57,"Met","Breached")) -> Met | S57: Aman Verma | T57: Identity & Access | U57: 5.6 | V57: Bengaluru | W57: =COUNTIF($A$2:$A$321,A57) -> 1
A58: TKT-0057 | B58: 46201.96 | C58: 46201.98 | D58: 46202.145 | E58: Closed | F58: High | G58: CRM / Sales App | H58: Operations | I58: Portal | J58: A010 | K58: No | L58: 4 | M58: =IF(OR(B58="",C58=""),"",24*(C58-B58)) -> 0.48607028 | N58: =IF(OR(B58="",D58=""),"",24*(D58-B58)) -> 4.4424231 | O58: =VLOOKUP(F58,SLA_Targets!$A$2:$C$5,2,FALSE) -> 1 | P58: =VLOOKUP(F58,SLA_Targets!$A$2:$C$5,3,FALSE) -> 8 | Q58: =IF(M58="","Pending",IF(M58<=O58,"Met","Breached")) -> Met | R58: =IF(N58="","Pending",IF(N58<=P58,"Met","Breached")) -> Met | S58: Rohan Sen | T58: Business Apps | U58: 4.8 | V58: Kolkata | W58: =COUNTIF($A$2:$A$321,A58) -> 1
...

Sheet Project_Brief
A1: IT Helpdesk Operations & SLA Analysis
A2: Goal: identify service bottlenecks, SLA breaches, workload imbalance, and service-quality issues.
A3: Final output: cleaned analysis table + KPI section + PivotTable analysis + one-page dashboard.
A4: Use Agent_ID to enrich tickets from Agent_Master.
A5: Use Priority to look up response/resolution targets from SLA_Targets.
A6: Intentional issues: inconsistent Department values, 5 duplicate ticket rows, meaningful blank CSAT/resolution cells.
A7: Suggested questions: SLA compliance by priority/category/team; workload by team/agent; CSAT vs SLA; reopened-ticket performance; department demand; monthly trend.

Sheet Analysis
A1: IT Helpdesk Analysis
A3: Overall KPI | B3: Value | D3: Response SLA Status | E3: Tickets | F3: Share | H3: Resolution SLA Status | I3: Tickets | J3: Share | O3: Issue Category | P3: Resolution SLA %
A4: Total Tickets | B4: =COUNTA(Clean_Tickets!$A$2:$A$321) -> 320 | D4: Met | E4: =COUNTIF(Clean_Tickets!$Q$2:$Q$321,D4) -> 240 | F4: =E4/SUM($E$4:$E$6) -> 0.75 | H4: Met | I4: =COUNTIF(Clean_Tickets!$R$2:$R$321,H4) -> 213 | J4: =I4/SUM($I$4:$I$6) -> 0.665625 | O4: =A26 -> Password / Access | P4: =I26 -> 0.94642857
A5: Closed / Resolved | B5: =COUNTIF(Clean_Tickets!$E$2:$E$321,"Closed")+COUNTIF(Clean_Tickets!$E$2:$E$321,"Resolved") -> 304 | D5: Breached | E5: =COUNTIF(Clean_Tickets!$Q$2:$Q$321,D5) -> 80 | F5: =E5/SUM($E$4:$E$6) -> 0.25 | H5: Breached | I5: =COUNTIF(Clean_Tickets!$R$2:$R$321,H5) -> 91 | J5: =I5/SUM($I$4:$I$6) -> 0.284375 | O5: =A27 -> Laptop / Hardware | P5: =I27 -> 0.60416667
A6: Open / In Progress | B6: =COUNTIF(Clean_Tickets!$E$2:$E$321,"Pending")+COUNTIF(Clean_Tickets!$E$2:$E$321,"In Progress") -> 16 | D6: Pending | E6: =COUNTIF(Clean_Tickets!$Q$2:$Q$321,D6) -> 0 | F6: =E6/SUM($E$4:$E$6) -> 0 | H6: Pending | I6: =COUNTIF(Clean_Tickets!$R$2:$R$321,H6) -> 16 | J6: =I6/SUM($I$4:$I$6) -> 0.05 | O6: =A28 -> Email / Collaboration | P6: =I28 -> 0.78571429
A7: Reopened Tickets | B7: =COUNTIF(Clean_Tickets!$K$2:$K$321,"Yes") -> 36 | O7: =A29 -> VPN / Network | P7: =I29 -> 0.74358974
A8: Reopen Rate | B8: =B7/B4 -> 0.1125 | O8: =A30 -> ERP / Finance App | P8: =I30 -> 0.57142857
A9: Avg First Response (hrs) | B9: =SUM(Clean_Tickets!$M$2:$M$321)/COUNT(Clean_Tickets!$M$2:$M$321) -> 2.6397433 | O9: =A31 -> CRM / Sales App | P9: =I31 -> 0.5
A10: Avg Resolution (hrs) | B10: =SUM(Clean_Tickets!$N$2:$N$321)/COUNT(Clean_Tickets!$N$2:$N$321) -> 18.108642 | O10: =A32 -> Server / Connectivity | P10: =I32 -> 0.46875
A11: Avg CSAT | B11: =SUM(Clean_Tickets!$L$2:$L$321)/COUNT(Clean_Tickets!$L$2:$L$321) -> 4.1118421 | O11: =A33 -> Printer / Peripheral | P11: =I33 -> 0.9
A12: Response SLA Compliance | B12: =COUNTIF(Clean_Tickets!$Q$2:$Q$321,"Met")/(COUNTIF(Clean_Tickets!$Q$2:$Q$321,"Met")+COUNTIF(Clean_Tickets!$Q$2:$Q$321,"Breached")) -> 0.75
A13: Resolution SLA Compliance | B13: =COUNTIF(Clean_Tickets!$R$2:$R$321,"Met")/(COUNTIF(Clean_Tickets!$R$2:$R$321,"Met")+COUNTIF(Clean_Tickets!$R$2:$R$321,"Breached")) -> 0.70065789
O14: Support Team | P14: Resolution SLA %
O15: =A50 -> Workplace Support | P15: =I50 -> 0.72727273
A16: Priority Analysis | O16: =A51 -> Network & Infra | P16: =I51 -> 0.61971831
A17: Group | B17: Tickets | C17: Resp Met | D17: Resp Breached | E17: Resp SLA % | F17: Res Met | G17: Res Breached | H17: Res Pending | I17: Res SLA % | J17: Avg Resp Hrs | K17: Avg Res Hrs | L17: Avg CSAT | M17: Reopened | O17: =A52 -> Business Apps | P17: =I52 -> 0.53731343
A18: Critical | B18: =COUNTIF(Clean_Tickets!$F$2:$F$321,A18) -> 60 | C18: =COUNTIFS(Clean_Tickets!$F$2:$F$321,A18,Clean_Tickets!$Q$2:$Q$321,"Met") -> 54 | D18: =COUNTIFS(Clean_Tickets!$F$2:$F$321,A18,Clean_Tickets!$Q$2:$Q$321,"Breached") -> 6 | E18: =IFERROR(C18/(C18+D18),0) -> 0.9 | F18: =COUNTIFS(Clean_Tickets!$F$2:$F$321,A18,Clean_Tickets!$R$2:$R$321,"Met") -> 46 | G18: =COUNTIFS(Clean_Tickets!$F$2:$F$321,A18,Clean_Tickets!$R$2:$R$321,"Breached") -> 12 | H18: =COUNTIFS(Clean_Tickets!$F$2:$F$321,A18,Clean_Tickets!$R$2:$R$321,"Pending") -> 2 | I18: =IFERROR(F18/(F18+G18),0) -> 0.79310345 | J18: =IFERROR(SUMIF(Clean_Tickets!$F$2:$F$321,A18,Clean_Tickets!$M$2:$M$321)/COUNTIF(Clean_Tickets!$F$2:$F$321,A18),0) -> 0.28721683 | K18: =IFERROR(SUMIF(Clean_Tickets!$F$2:$F$321,A18,Clean_Tickets!$N$2:$N$321)/(COUNTIFS(Clean_Tickets!$F$2:$F$321,A18,Clean_Tickets!$E$2:$E$321,"Closed")+COUNTIFS(Clean_Tickets!$F$2:$F$321,A18,Clean_Tickets!$E$2:$E$321,"Resolved")),0) -> 2.9809526 | L18: =IFERROR(SUMIF(Clean_Tickets!$F$2:$F$321,A18,Clean_Tickets!$L$2:$L$321)/COUNTIFS(Clean_Tickets!$F$2:$F$321,A18,Clean_Tickets!$L$2:$L$321,">0"),0) -> 4.2068966 | M18: =COUNTIFS(Clean_Tickets!$F$2:$F$321,A18,Clean_Tickets!$K$2:$K$321,"Yes") -> 8 | O18: =A53 -> Identity & Access | P18: =I53 -> 0.94642857
A19: High | B19: =COUNTIF(Clean_Tickets!$F$2:$F$321,A19) -> 84 | C19: =COUNTIFS(Clean_Tickets!$F$2:$F$321,A19,Clean_Tickets!$Q$2:$Q$321,"Met") -> 58 | D19: =COUNTIFS(Clean_Tickets!$F$2:$F$321,A19,Clean_Tickets!$Q$2:$Q$321,"Breached") -> 26 | E19: =IFERROR(C19/(C19+D19),0) -> 0.69047619 | F19: =COUNTIFS(Clean_Tickets!$F$2:$F$321,A19,Clean_Tickets!$R$2:$R$321,"Met") -> 55 | G19: =COUNTIFS(Clean_Tickets!$F$2:$F$321,A19,Clean_Tickets!$R$2:$R$321,"Breached") -> 26 | H19: =COUNTIFS(Clean_Tickets!$F$2:$F$321,A19,Clean_Tickets!$R$2:$R$321,"Pending") -> 3 | I19: =IFERROR(F19/(F19+G19),0) -> 0.67901235 | J19: =IFERROR(SUMIF(Clean_Tickets!$F$2:$F$321,A19,Clean_Tickets!$M$2:$M$321)/COUNTIF(Clean_Tickets!$F$2:$F$321,A19),0) -> 0.88231727 | K19: =IFERROR(SUMIF(Clean_Tickets!$F$2:$F$321,A19,Clean_Tickets!$N$2:$N$321)/(COUNTIFS(Clean_Tickets!$F$2:$F$321,A19,Clean_Tickets!$E$2:$E$321,"Closed")+COUNTIFS(Clean_Tickets!$F$2:$F$321,A19,Clean_Tickets!$E$2:$E$321,"Resolved")),0) -> 7.2748293 | L19: =IFERROR(SUMIF(Clean_Tickets!$F$2:$F$321,A19,Clean_Tickets!$L$2:$L$321)/COUNTIFS(Clean_Tickets!$F$2:$F$321,A19,Clean_Tickets!$L$2:$L$321,">0"),0) -> 4.0617284 | M19: =COUNTIFS(Clean_Tickets!$F$2:$F$321,A19,Clean_Tickets!$K$2:$K$321,"Yes") -> 11
A20: Medium | B20: =COUNTIF(Clean_Tickets!$F$2:$F$321,A20) -> 127 | C20: =COUNTIFS(Clean_Tickets!$F$2:$F$321,A20,Clean_Tickets!$Q$2:$Q$321,"Met") -> 94 | D20: =COUNTIFS(Clean_Tickets!$F$2:$F$321,A20,Clean_Tickets!$Q$2:$Q$321,"Breached") -> 33 | E20: =IFERROR(C20/(C20+D20),0) -> 0.74015748 | F20: =COUNTIFS(Clean_Tickets!$F$2:$F$321,A20,Clean_Tickets!$R$2:$R$321,"Met") -> 82 | G20: =COUNTIFS(Clean_Tickets!$F$2:$F$321,A20,Clean_Tickets!$R$2:$R$321,"Breached") -> 38 | H20: =COUNTIFS(Clean_Tickets!$F$2:$F$321,A20,Clean_Tickets!$R$2:$R$321,"Pending") -> 7 | I20: =IFERROR(F20/(F20+G20),0) -> 0.68333333 | J20: =IFERROR(SUMIF(Clean_Tickets!$F$2:$F$321,A20,Clean_Tickets!$M$2:$M$321)/COUNTIF(Clean_Tickets!$F$2:$F$321,A20),0) -> 3.3539497 | K20: =IFERROR(SUMIF(Clean_Tickets!$F$2:$F$321,A20,Clean_Tickets!$N$2:$N$321)/(COUNTIFS(Clean_Tickets!$F$2:$F$321,A20,Clean_Tickets!$E$2:$E$321,"Closed")+COUNTIFS(Clean_Tickets!$F$2:$F$321,A20,Clean_Tickets!$E$2:$E$321,"Resolved")),0) -> 20.976325 | L20: =IFERROR(SUMIF(Clean_Tickets!$F$2:$F$321,A20,Clean_Tickets!$L$2:$L$321)/COUNTIFS(Clean_Tickets!$F$2:$F$321,A20,Clean_Tickets!$L$2:$L$321,">0"),0) -> 4.075 | M20: =COUNTIFS(Clean_Tickets!$F$2:$F$321,A20,Clean_Tickets!$K$2:$K$321,"Yes") -> 13
A21: Low | B21: =COUNTIF(Clean_Tickets!$F$2:$F$321,A21) -> 49 | C21: =COUNTIFS(Clean_Tickets!$F$2:$F$321,A21,Clean_Tickets!$Q$2:$Q$321,"Met") -> 34 | D21: =COUNTIFS(Clean_Tickets!$F$2:$F$321,A21,Clean_Tickets!$Q$2:$Q$321,"Breached") -> 15 | E21: =IFERROR(C21/(C21+D21),0) -> 0.69387755 | F21: =COUNTIFS(Clean_Tickets!$F$2:$F$321,A21,Clean_Tickets!$R$2:$R$321,"Met") -> 30 | G21: =COUNTIFS(Clean_Tickets!$F$2:$F$321,A21,Clean_Tickets!$R$2:$R$321,"Breached") -> 15 | H21: =COUNTIFS(Clean_Tickets!$F$2:$F$321,A21,Clean_Tickets!$R$2:$R$321,"Pending") -> 4 | I21: =IFERROR(F21/(F21+G21),0) -> 0.66666667 | J21: =IFERROR(SUMIF(Clean_Tickets!$F$2:$F$321,A21,Clean_Tickets!$M$2:$M$321)/COUNTIF(Clean_Tickets!$F$2:$F$321,A21),0) -> 6.6820116 | K21: =IFERROR(SUMIF(Clean_Tickets!$F$2:$F$321,A21,Clean_Tickets!$N$2:$N$321)/(COUNTIFS(Clean_Tickets!$F$2:$F$321,A21,Clean_Tickets!$E$2:$E$321,"Closed")+COUNTIFS(Clean_Tickets!$F$2:$F$321,A21,Clean_Tickets!$E$2:$E$321,"Resolved")),0) -> 49.460258 | L21: =IFERROR(SUMIF(Clean_Tickets!$F$2:$F$321,A21,Clean_Tickets!$L$2:$L$321)/COUNTIFS(Clean_Tickets!$F$2:$F$321,A21,Clean_Tickets!$L$2:$L$321,">0"),0) -> 4.1777778 | M21: =COUNTIFS(Clean_Tickets!$F$2:$F$321,A21,Clean_Tickets!$K$2:$K$321,"Yes") -> 4
A24: Issue Category Analysis
A25: Group | B25: Tickets | C25: Resp Met | D25: Resp Breached | E25: Resp SLA % | F25: Res Met | G25: Res Breached | H25: Res Pending | I25: Res SLA % | J25: Avg Resp Hrs | K25: Avg Res Hrs | L25: Avg CSAT | M25: Reopened
A26: Password / Access | B26: =COUNTIF(Clean_Tickets!$G$2:$G$321,A26) -> 57 | C26: =COUNTIFS(Clean_Tickets!$G$2:$G$321,A26,Clean_Tickets!$Q$2:$Q$321,"Met") -> 51 | D26: =COUNTIFS(Clean_Tickets!$G$2:$G$321,A26,Clean_Tickets!$Q$2:$Q$321,"Breached") -> 6 | E26: =IFERROR(C26/(C26+D26),0) -> 0.89473684 | F26: =COUNTIFS(Clean_Tickets!$G$2:$G$321,A26,Clean_Tickets!$R$2:$R$321,"Met") -> 53 | G26: =COUNTIFS(Clean_Tickets!$G$2:$G$321,A26,Clean_Tickets!$R$2:$R$321,"Breached") -> 3 | H26: =COUNTIFS(Clean_Tickets!$G$2:$G$321,A26,Clean_Tickets!$R$2:$R$321,"Pending") -> 1 | I26: =IFERROR(F26/(F26+G26),0) -> 0.94642857 | J26: =IFERROR(SUMIF(Clean_Tickets!$G$2:$G$321,A26,Clean_Tickets!$M$2:$M$321)/COUNTIF(Clean_Tickets!$G$2:$G$321,A26),0) -> 0.95079506 | K26: =IFERROR(SUMIF(Clean_Tickets!$G$2:$G$321,A26,Clean_Tickets!$N$2:$N$321)/(COUNTIFS(Clean_Tickets!$G$2:$G$321,A26,Clean_Tickets!$E$2:$E$321,"Closed")+COUNTIFS(Clean_Tickets!$G$2:$G$321,A26,Clean_Tickets!$E$2:$E$321,"Resolved")),0) -> 5.2940632 | L26: =IFERROR(SUMIF(Clean_Tickets!$G$2:$G$321,A26,Clean_Tickets!$L$2:$L$321)/COUNTIFS(Clean_Tickets!$G$2:$G$321,A26,Clean_Tickets!$L$2:$L$321,">0"),0) -> 4.2321429 | M26: =COUNTIFS(Clean_Tickets!$G$2:$G$321,A26,Clean_Tickets!$K$2:$K$321,"Yes") -> 7
A27: Laptop / Hardware | B27: =COUNTIF(Clean_Tickets!$G$2:$G$321,A27) -> 53 | C27: =COUNTIFS(Clean_Tickets!$G$2:$G$321,A27,Clean_Tickets!$Q$2:$Q$321,"Met") -> 30 | D27: =COUNTIFS(Clean_Tickets!$G$2:$G$321,A27,Clean_Tickets!$Q$2:$Q$321,"Breached") -> 23 | E27: =IFERROR(C27/(C27+D27),0) -> 0.56603774 | F27: =COUNTIFS(Clean_Tickets!$G$2:$G$321,A27,Clean_Tickets!$R$2:$R$321,"Met") -> 29 | G27: =COUNTIFS(Clean_Tickets!$G$2:$G$321,A27,Clean_Tickets!$R$2:$R$321,"Breached") -> 19 | H27: =COUNTIFS(Clean_Tickets!$G$2:$G$321,A27,Clean_Tickets!$R$2:$R$321,"Pending") -> 5 | I27: =IFERROR(F27/(F27+G27),0) -> 0.60416667 | J27: =IFERROR(SUMIF(Clean_Tickets!$G$2:$G$321,A27,Clean_Tickets!$M$2:$M$321)/COUNTIF(Clean_Tickets!$G$2:$G$321,A27),0) -> 4.8761723 | K27: =IFERROR(SUMIF(Clean_Tickets!$G$2:$G$321,A27,Clean_Tickets!$N$2:$N$321)/(COUNTIFS(Clean_Tickets!$G$2:$G$321,A27,Clean_Tickets!$E$2:$E$321,"Closed")+COUNTIFS(Clean_Tickets!$G$2:$G$321,A27,Clean_Tickets!$E$2:$E$321,"Resolved")),0) -> 32.797929 | L27: =IFERROR(SUMIF(Clean_Tickets!$G$2:$G$321,A27,Clean_Tickets!$L$2:$L$321)/COUNTIFS(Clean_Tickets!$G$2:$G$321,A27,Clean_Tickets!$L$2:$L$321,">0"),0) -> 4 | M27: =COUNTIFS(Clean_Tickets!$G$2:$G$321,A27,Clean_Tickets!$K$2:$K$321,"Yes") -> 5
A28: Email / Collaboration | B28: =COUNTIF(Clean_Tickets!$G$2:$G$321,A28) -> 45 | C28: =COUNTIFS(Clean_Tickets!$G$2:$G$321,A28,Clean_Tickets!$Q$2:$Q$321,"Met") -> 39 | D28: =COUNTIFS(Clean_Tickets!$G$2:$G$321,A28,Clean_Tickets!$Q$2:$Q$321,"Breached") -> 6 | E28: =IFERROR(C28/(C28+D28),0) -> 0.86666667 | F28: =COUNTIFS(Clean_Tickets!$G$2:$G$321,A28,Clean_Tickets!$R$2:$R$321,"Met") -> 33 | G28: =COUNTIFS(Clean_Tickets!$G$2:$G$321,A28,Clean_Tickets!$R$2:$R$321,"Breached") -> 9 | H28: =COUNTIFS(Clean_Tickets!$G$2:$G$321,A28,Clean_Tickets!$R$2:$R$321,"Pending") -> 3 | I28: =IFERROR(F28/(F28+G28),0) -> 0.78571429 | J28: =IFERROR(SUMIF(Clean_Tickets!$G$2:$G$321,A28,Clean_Tickets!$M$2:$M$321)/COUNTIF(Clean_Tickets!$G$2:$G$321,A28),0) -> 2.7938542 | K28: =IFERROR(SUMIF(Clean_Tickets!$G$2:$G$321,A28,Clean_Tickets!$N$2:$N$321)/(COUNTIFS(Clean_Tickets!$G$2:$G$321,A28,Clean_Tickets!$E$2:$E$321,"Closed")+COUNTIFS(Clean_Tickets!$G$2:$G$321,A28,Clean_Tickets!$E$2:$E$321,"Resolved")),0) -> 17.377044 | L28: =IFERROR(SUMIF(Clean_Tickets!$G$2:$G$321,A28,Clean_Tickets!$L$2:$L$321)/COUNTIFS(Clean_Tickets!$G$2:$G$321,A28,Clean_Tickets!$L$2:$L$321,">0"),0) -> 4.3095238 | M28: =COUNTIFS(Clean_Tickets!$G$2:$G$321,A28,Clean_Tickets!$K$2:$K$321,"Yes") -> 4
A29: VPN / Network | B29: =COUNTIF(Clean_Tickets!$G$2:$G$321,A29) -> 40 | C29: =COUNTIFS(Clean_Tickets!$G$2:$G$321,A29,Clean_Tickets!$Q$2:$Q$321,"Met") -> 32 | D29: =COUNTIFS(Clean_Tickets!$G$2:$G$321,A29,Clean_Tickets!$Q$2:$Q$321,"Breached") -> 8 | E29: =IFERROR(C29/(C29+D29),0) -> 0.8 | F29: =COUNTIFS(Clean_Tickets!$G$2:$G$321,A29,Clean_Tickets!$R$2:$R$321,"Met") -> 29 | G29: =COUNTIFS(Clean_Tickets!$G$2:$G$321,A29,Clean_Tickets!$R$2:$R$321,"Breached") -> 10 | H29: =COUNTIFS(Clean_Tickets!$G$2:$G$321,A29,Clean_Tickets!$R$2:$R$321,"Pending") -> 1 | I29: =IFERROR(F29/(F29+G29),0) -> 0.74358974 | J29: =IFERROR(SUMIF(Clean_Tickets!$G$2:$G$321,A29,Clean_Tickets!$M$2:$M$321)/COUNTIF(Clean_Tickets!$G$2:$G$321,A29),0) -> 1.5432488 | K29: =IFERROR(SUMIF(Clean_Tickets!$G$2:$G$321,A29,Clean_Tickets!$N$2:$N$321)/(COUNTIFS(Clean_Tickets!$G$2:$G$321,A29,Clean_Tickets!$E$2:$E$321,"Closed")+COUNTIFS(Clean_Tickets!$G$2:$G$321,A29,Clean_Tickets!$E$2:$E$321,"Resolved")),0) -> 11.624127 | L29: =IFERROR(SUMIF(Clean_Tickets!$G$2:$G$321,A29,Clean_Tickets!$L$2:$L$321)/COUNTIFS(Clean_Tickets!$G$2:$G$321,A29,Clean_Tickets!$L$2:$L$321,">0"),0) -> 4.2307692 | M29: =COUNTIFS(Clean_Tickets!$G$2:$G$321,A29,Clean_Tickets!$K$2:$K$321,"Yes") -> 3
A30: ERP / Finance App | B30: =COUNTIF(Clean_Tickets!$G$2:$G$321,A30) -> 36 | C30: =COUNTIFS(Clean_Tickets!$G$2:$G$321,A30,Clean_Tickets!$Q$2:$Q$321,"Met") -> 23 | D30: =COUNTIFS(Clean_Tickets!$G$2:$G$321,A30,Clean_Tickets!$Q$2:$Q$321,"Breached") -> 13 | E30: =IFERROR(C30/(C30+D30),0) -> 0.63888889 | F30: =COUNTIFS(Clean_Tickets!$G$2:$G$321,A30,Clean_Tickets!$R$2:$R$321,"Met") -> 20 | G30: =COUNTIFS(Clean_Tickets!$G$2:$G$321,A30,Clean_Tickets!$R$2:$R$321,"Breached") -> 15 | H30: =COUNTIFS(Clean_Tickets!$G$2:$G$321,A30,Clean_Tickets!$R$2:$R$321,"Pending") -> 1 | I30: =IFERROR(F30/(F30+G30),0) -> 0.57142857 | J30: =IFERROR(SUMIF(Clean_Tickets!$G$2:$G$321,A30,Clean_Tickets!$M$2:$M$321)/COUNTIF(Clean_Tickets!$G$2:$G$321,A30),0) -> 2.8171476 | K30: =IFERROR(SUMIF(Clean_Tickets!$G$2:$G$321,A30,Clean_Tickets!$N$2:$N$321)/(COUNTIFS(Clean_Tickets!$G$2:$G$321,A30,Clean_Tickets!$E$2:$E$321,"Closed")+COUNTIFS(Clean_Tickets!$G$2:$G$321,A30,Clean_Tickets!$E$2:$E$321,"Resolved")),0) -> 19.518492 | L30: =IFERROR(SUMIF(Clean_Tickets!$G$2:$G$321,A30,Clean_Tickets!$L$2:$L$321)/COUNTIFS(Clean_Tickets!$G$2:$G$321,A30,Clean_Tickets!$L$2:$L$321,">0"),0) -> 4.1142857 | M30: =COUNTIFS(Clean_Tickets!$G$2:$G$321,A30,Clean_Tickets!$K$2:$K$321,"Yes") -> 6
A31: CRM / Sales App | B31: =COUNTIF(Clean_Tickets!$G$2:$G$321,A31) -> 35 | C31: =COUNTIFS(Clean_Tickets!$G$2:$G$321,A31,Clean_Tickets!$Q$2:$Q$321,"Met") -> 24 | D31: =COUNTIFS(Clean_Tickets!$G$2:$G$321,A31,Clean_Tickets!$Q$2:$Q$321,"Breached") -> 11 | E31: =IFERROR(C31/(C31+D31),0) -> 0.68571429 | F31: =COUNTIFS(Clean_Tickets!$G$2:$G$321,A31,Clean_Tickets!$R$2:$R$321,"Met") -> 16 | G31: =COUNTIFS(Clean_Tickets!$G$2:$G$321,A31,Clean_Tickets!$R$2:$R$321,"Breached") -> 16 | H31: =COUNTIFS(Clean_Tickets!$G$2:$G$321,A31,Clean_Tickets!$R$2:$R$321,"Pending") -> 3 | I31: =IFERROR(F31/(F31+G31),0) -> 0.5 | J31: =IFERROR(SUMIF(Clean_Tickets!$G$2:$G$321,A31,Clean_Tickets!$M$2:$M$321)/COUNTIF(Clean_Tickets!$G$2:$G$321,A31),0) -> 3.2866832 | K31: =IFERROR(SUMIF(Clean_Tickets!$G$2:$G$321,A31,Clean_Tickets!$N$2:$N$321)/(COUNTIFS(Clean_Tickets!$G$2:$G$321,A31,Clean_Tickets!$E$2:$E$321,"Closed")+COUNTIFS(Clean_Tickets!$G$2:$G$321,A31,Clean_Tickets!$E$2:$E$321,"Resolved")),0) -> 23.949574 | L31: =IFERROR(SUMIF(Clean_Tickets!$G$2:$G$321,A31,Clean_Tickets!$L$2:$L$321)/COUNTIFS(Clean_Tickets!$G$2:$G$321,A31,Clean_Tickets!$L$2:$L$321,">0"),0) -> 3.96875 | M31: =COUNTIFS(Clean_Tickets!$G$2:$G$321,A31,Clean_Tickets!$K$2:$K$321,"Yes") -> 2
A32: Server / Connectivity | B32: =COUNTIF(Clean_Tickets!$G$2:$G$321,A32) -> 34 | C32: =COUNTIFS(Clean_Tickets!$G$2:$G$321,A32,Clean_Tickets!$Q$2:$Q$321,"Met") -> 22 | D32: =COUNTIFS(Clean_Tickets!$G$2:$G$321,A32,Clean_Tickets!$Q$2:$Q$321,"Breached") -> 12 | E32: =IFERROR(C32/(C32+D32),0) -> 0.64705882 | F32: =COUNTIFS(Clean_Tickets!$G$2:$G$321,A32,Clean_Tickets!$R$2:$R$321,"Met") -> 15 | G32: =COUNTIFS(Clean_Tickets!$G$2:$G$321,A32,Clean_Tickets!$R$2:$R$321,"Breached") -> 17 | H32: =COUNTIFS(Clean_Tickets!$G$2:$G$321,A32,Clean_Tickets!$R$2:$R$321,"Pending") -> 2 | I32: =IFERROR(F32/(F32+G32),0) -> 0.46875 | J32: =IFERROR(SUMIF(Clean_Tickets!$G$2:$G$321,A32,Clean_Tickets!$M$2:$M$321)/COUNTIF(Clean_Tickets!$G$2:$G$321,A32),0) -> 2.0048028 | K32: =IFERROR(SUMIF(Clean_Tickets!$G$2:$G$321,A32,Clean_Tickets!$N$2:$N$321)/(COUNTIFS(Clean_Tickets!$G$2:$G$321,A32,Clean_Tickets!$E$2:$E$321,"Closed")+COUNTIFS(Clean_Tickets!$G$2:$G$321,A32,Clean_Tickets!$E$2:$E$321,"Resolved")),0) -> 18.919003 | L32: =IFERROR(SUMIF(Clean_Tickets!$G$2:$G$321,A32,Clean_Tickets!$L$2:$L$321)/COUNTIFS(Clean_Tickets!$G$2:$G$321,A32,Clean_Tickets!$L$2:$L$321,">0"),0) -> 3.71875 | M32: =COUNTIFS(Clean_Tickets!$G$2:$G$321,A32,Clean_Tickets!$K$2:$K$321,"Yes") -> 6
A33: Printer / Peripheral | B33: =COUNTIF(Clean_Tickets!$G$2:$G$321,A33) -> 20 | C33: =COUNTIFS(Clean_Tickets!$G$2:$G$321,A33,Clean_Tickets!$Q$2:$Q$321,"Met") -> 19 | D33: =COUNTIFS(Clean_Tickets!$G$2:$G$321,A33,Clean_Tickets!$Q$2:$Q$321,"Breached") -> 1 | E33: =IFERROR(C33/(C33+D33),0) -> 0.95 | F33: =COUNTIFS(Clean_Tickets!$G$2:$G$321,A33,Clean_Tickets!$R$2:$R$321,"Met") -> 18 | G33: =COUNTIFS(Clean_Tickets!$G$2:$G$321,A33,Clean_Tickets!$R$2:$R$321,"Breached") -> 2 | H33: =COUNTIFS(Clean_Tickets!$G$2:$G$321,A33,Clean_Tickets!$R$2:$R$321,"Pending") -> 0 | I33: =IFERROR(F33/(F33+G33),0) -> 0.9 | J33: =IFERROR(SUMIF(Clean_Tickets!$G$2:$G$321,A33,Clean_Tickets!$M$2:$M$321)/COUNTIF(Clean_Tickets!$G$2:$G$321,A33),0) -> 3.000874 | K33: =IFERROR(SUMIF(Clean_Tickets!$G$2:$G$321,A33,Clean_Tickets!$N$2:$N$321)/(COUNTIFS(Clean_Tickets!$G$2:$G$321,A33,Clean_Tickets!$E$2:$E$321,"Closed")+COUNTIFS(Clean_Tickets!$G$2:$G$321,A33,Clean_Tickets!$E$2:$E$321,"Resolved")),0) -> 19.807022 | L33: =IFERROR(SUMIF(Clean_Tickets!$G$2:$G$321,A33,Clean_Tickets!$L$2:$L$321)/COUNTIFS(Clean_Tickets!$G$2:$G$321,A33,Clean_Tickets!$L$2:$L$321,">0"),0) -> 4.25 | M33: =COUNTIFS(Clean_Tickets!$G$2:$G$321,A33,Clean_Tickets!$K$2:$K$321,"Yes") -> 3
A36: Department Analysis
A37: Group | B37: Tickets | C37: Resp Met | D37: Resp Breached | E37: Resp SLA % | F37: Res Met | G37: Res Breached | H37: Res Pending | I37: Res SLA % | J37: Avg Resp Hrs | K37: Avg Res Hrs | L37: Avg CSAT | M37: Reopened
A38: Operations | B38: =COUNTIF(Clean_Tickets!$H$2:$H$321,A38) -> 50 | C38: =COUNTIFS(Clean_Tickets!$H$2:$H$321,A38,Clean_Tickets!$Q$2:$Q$321,"Met") -> 38 | D38: =COUNTIFS(Clean_Tickets!$H$2:$H$321,A38,Clean_Tickets!$Q$2:$Q$321,"Breached") -> 12 | E38: =IFERROR(C38/(C38+D38),0) -> 0.76 | F38: =COUNTIFS(Clean_Tickets!$H$2:$H$321,A38,Clean_Tickets!$R$2:$R$321,"Met") -> 44 | G38: =COUNTIFS(Clean_Tickets!$H$2:$H$321,A38,Clean_Tickets!$R$2:$R$321,"Breached") -> 5 | H38: =COUNTIFS(Clean_Tickets!$H$2:$H$321,A38,Clean_Tickets!$R$2:$R$321,"Pending") -> 1 | I38: =IFERROR(F38/(F38+G38),0) -> 0.89795918 | J38: =IFERROR(SUMIF(Clean_Tickets!$H$2:$H$321,A38,Clean_Tickets!$M$2:$M$321)/COUNTIF(Clean_Tickets!$H$2:$H$321,A38),0) -> 1.9244818 | K38: =IFERROR(SUMIF(Clean_Tickets!$H$2:$H$321,A38,Clean_Tickets!$N$2:$N$321)/(COUNTIFS(Clean_Tickets!$H$2:$H$321,A38,Clean_Tickets!$E$2:$E$321,"Closed")+COUNTIFS(Clean_Tickets!$H$2:$H$321,A38,Clean_Tickets!$E$2:$E$321,"Resolved")),0) -> 9.8149538 | L38: =IFERROR(SUMIF(Clean_Tickets!$H$2:$H$321,A38,Clean_Tickets!$L$2:$L$321)/COUNTIFS(Clean_Tickets!$H$2:$H$321,A38,Clean_Tickets!$L$2:$L$321,">0"),0) -> 4.1632653 | M38: =COUNTIFS(Clean_Tickets!$H$2:$H$321,A38,Clean_Tickets!$K$2:$K$321,"Yes") -> 7
A39: Sales | B39: =COUNTIF(Clean_Tickets!$H$2:$H$321,A39) -> 44 | C39: =COUNTIFS(Clean_Tickets!$H$2:$H$321,A39,Clean_Tickets!$Q$2:$Q$321,"Met") -> 34 | D39: =COUNTIFS(Clean_Tickets!$H$2:$H$321,A39,Clean_Tickets!$Q$2:$Q$321,"Breached") -> 10 | E39: =IFERROR(C39/(C39+D39),0) -> 0.77272727 | F39: =COUNTIFS(Clean_Tickets!$H$2:$H$321,A39,Clean_Tickets!$R$2:$R$321,"Met") -> 28 | G39: =COUNTIFS(Clean_Tickets!$H$2:$H$321,A39,Clean_Tickets!$R$2:$R$321,"Breached") -> 14 | H39: =COUNTIFS(Clean_Tickets!$H$2:$H$321,A39,Clean_Tickets!$R$2:$R$321,"Pending") -> 2 | I39: =IFERROR(F39/(F39+G39),0) -> 0.66666667 | J39: =IFERROR(SUMIF(Clean_Tickets!$H$2:$H$321,A39,Clean_Tickets!$M$2:$M$321)/COUNTIF(Clean_Tickets!$H$2:$H$321,A39),0) -> 2.5184563 | K39: =IFERROR(SUMIF(Clean_Tickets!$H$2:$H$321,A39,Clean_Tickets!$N$2:$N$321)/(COUNTIFS(Clean_Tickets!$H$2:$H$321,A39,Clean_Tickets!$E$2:$E$321,"Closed")+COUNTIFS(Clean_Tickets!$H$2:$H$321,A39,Clean_Tickets!$E$2:$E$321,"Resolved")),0) -> 15.826176 | L39: =IFERROR(SUMIF(Clean_Tickets!$H$2:$H$321,A39,Clean_Tickets!$L$2:$L$321)/COUNTIFS(Clean_Tickets!$H$2:$H$321,A39,Clean_Tickets!$L$2:$L$321,">0"),0) -> 4.1190476 | M39: =COUNTIFS(Clean_Tickets!$H$2:$H$321,A39,Clean_Tickets!$K$2:$K$321,"Yes") -> 9
A40: Engineering | B40: =COUNTIF(Clean_Tickets!$H$2:$H$321,A40) -> 43 | C40: =COUNTIFS(Clean_Tickets!$H$2:$H$321,A40,Clean_Tickets!$Q$2:$Q$321,"Met") -> 30 | D40: =COUNTIFS(Clean_Tickets!$H$2:$H$321,A40,Clean_Tickets!$Q$2:$Q$321,"Breached") -> 13 | E40: =IFERROR(C40/(C40+D40),0) -> 0.69767442 | F40: =COUNTIFS(Clean_Tickets!$H$2:$H$321,A40,Clean_Tickets!$R$2:$R$321,"Met") -> 30 | G40: =COUNTIFS(Clean_Tickets!$H$2:$H$321,A40,Clean_Tickets!$R$2:$R$321,"Breached") -> 11 | H40: =COUNTIFS(Clean_Tickets!$H$2:$H$321,A40,Clean_Tickets!$R$2:$R$321,"Pending") -> 2 | I40: =IFERROR(F40/(F40+G40),0) -> 0.73170732 | J40: =IFERROR(SUMIF(Clean_Tickets!$H$2:$H$321,A40,Clean_Tickets!$M$2:$M$321)/COUNTIF(Clean_Tickets!$H$2:$H$321,A40),0) -> 2.7237099 | K40: =IFERROR(SUMIF(Clean_Tickets!$H$2:$H$321,A40,Clean_Tickets!$N$2:$N$321)/(COUNTIFS(Clean_Tickets!$H$2:$H$321,A40,Clean_Tickets!$E$2:$E$321,"Closed")+COUNTIFS(Clean_Tickets!$H$2:$H$321,A40,Clean_Tickets!$E$2:$E$321,"Resolved")),0) -> 18.142328 | L40: =IFERROR(SUMIF(Clean_Tickets!$H$2:$H$321,A40,Clean_Tickets!$L$2:$L$321)/COUNTIFS(Clean_Tickets!$H$2:$H$321,A40,Clean_Tickets!$L$2:$L$321,">0"),0) -> 4.1463415 | M40: =COUNTIFS(Clean_Tickets!$H$2:$H$321,A40,Clean_Tickets!$K$2:$K$321,"Yes") -> 5
